Workbook

Sheet query (18)
A1: ID | B1: Titre | C1: Date de l'Analyse | D1: Famille d'achat | E1: Segment | F1: Acheteur | G1: Sous famille | H1: Difficulté d’homologation venant des clients | I1: Diversité des outillages requis | J1: Dossier technique incomplet | K1: Qualité demandée inhabituelle sur le marché | L1: Services techniques peu ouverts aux produits de substitution | M1: Connaissance tardive des besoins | N1: Fournisseur imposé | O1: Limites géographiques imposées en interne | P1: Lourdeurs Administratives | Q1: Manque de communication interne | R1: Dépendance fournisseur | S1: Non-conformité réglementaire | T1: Problèmes de qualité | U1: Rupture d’approvisionnement | V1: Manque de transparence fournisseur | W1: Risque de dépendance technologique | X1: Insatisfaction des clients internes | Y1: Variabilité des coûts | Z1: Renforcement de la chaîne d’approvisionnement | AA1: Optimisation des coûts | AB1: Innovation fournisseur | AC1: Réduction des délais de livraison | AD1: Meilleure maîtrise des risque | AE1: Amélioration des relations fournisseurs | AF1: Automatisation et digitalisation | AG1: Amélioration de l’image RSE | AH1: Couverture contractuelle | AI1: Plan d'action | AJ1: Programmation | AK1: Levier Achat | AL1: Total_Opportun | AM1: Total_Risques | AN1: Total_CIT | AO1: Total_CIC | AP1: Total_CET | AQ1: Total_CEC | AR1: Type d'élément | AS1: Chemin d'accès | AT1: Montant commandé (K€)
A2: 6 | B2: Informatique & Telecom - Systèmes d'impression | C2: 46105 | D2: Systèmes d'impression | E2: Informatique & Telecom | F2: Julie GAUJARD | H2: 2 l’achat n’est remis en question que pour quelques pièces, | I2: 3 entraîne une réduction du nombre de fournisseurs potentiels, | J2: 3 reporte l’achat à cause d’une refonte nécessaire du dossier technique, | K2: 1 la forte concurrence amène les fournisseurs à s’adapter, | L2: 0 aucune difficulté pour recourir à des produits de substitution, | M2: 5 les achats ne sont que des achats d’urgence par manque de prévisions. | N2: 1 les impositions correspondent au meilleur choix, | O2: 0 il n’y a pas de limite géographique à l’achat, | P2: 4 le changement de fournisseur est long et fastidieux du fait des procédures administratives, | Q2: 5 le défaut de communication interne est à l’origine d’achats réalisés dans des conditions défavorables. | R2: 0 - Nul | S2: 0 - Nul | T2: 1 - Faible | U2: 3 - Important | V2: 1 - Faible | W2: 0 - Nul | X2: 3 - Important | Y2: 1 - Faible | Z2: 1 - Faible | AA2: 2 - Modéré | AC2: 1 - Faible | AD2: 1 - Faible | AE2: 1 - Faible | AF2: 1 - Faible | AG2: 3 - Important | AH2: 0 - Sécurisé | AJ2: T4 2028 | AL2: 0 | AM2: 0 | AN2: 7.2 | AO2: 12 | AP2: 0 | AQ2: 0 | AR2: Élément | AS2: sites/DNA948/Lists/Analyse de Portefeuille FINA | AT2: =IFERROR(ROUND(IF(Tableau_query__18[[#This Row],[Sous famille]]<>"",VLOOKUP(Tableau_query__18[[#This Row],[Sous famille]],'A013 TCD'!G:H,2,FALSE),VLOOKUP(Tableau_query__18[[#This Row],[Famille d''achat]],'A013 TCD'!D:E,2,FALSE))/1000,0),"") -> 1827
A3: 7 | B3: Informatique & Telecom - Services de Téléphonie | C3: 45916 | D3: Services de Téléphonie | E3: Informatique & Telecom | F3: Julie GAUJARD | H3: 1 les modifications sont minimes et sans conséquence sur l’achat, | I3: 0 égale à la moyenne du secteur, | J3: 2 retarde l’achat en l’absence de responsabilité technique, | K3: 0 la qualité demandée correspond à la moyenne du marché, | L3: 0 aucune difficulté pour recourir à des produits de substitution, | M3: 5 les achats ne sont que des achats d’urgence par manque de prévisions. | N3: 1 les impositions correspondent au meilleur choix, | O3: 0 il n’y a pas de limite géographique à l’achat, | P3: 4 le changement de fournisseur est long et fastidieux du fait des procédures administratives, | Q3: 5 le défaut de communication interne est à l’origine d’achats réalisés dans des conditions défavorables. | R3: 0 - Nul | S3: 0 - Nul | T3: 1 - Faible | U3: 1 - Faible | V3: 1 - Faible | W3: 0 - Nul | X3: 2 - Modéré | Y3: 2 - Modéré | Z3: 1 - Faible | AA3: 2 - Modéré | AB3: 0 - Nul | AC3: 1 - Faible | AD3: 1 - Faible | AE3: 2 - Modéré | AF3: 1 - Faible | AG3: 3 - Important | AH3: 0 - Sécurisé | AI3: Etudier le recours à une central d'achat car achats simples | AJ3: T2 2027 | AL3: 5.5 | AM3: 3.5 | AN3: 2.4 | AO3: 0 | AP3: 0 | AQ3: 0 | AR3: Élément | AS3: sites/DNA948/Lists/Analyse de Portefeuille FINA | AT3: =IFERROR(ROUND(IF(Tableau_query__18[[#This Row],[Sous famille]]<>"",VLOOKUP(Tableau_query__18[[#This Row],[Sous famille]],'A013 TCD'!G:H,2,FALSE),VLOOKUP(Tableau_query__18[[#This Row],[Famille d''achat]],'A013 TCD'!D:E,2,FALSE))/1000,0),"") -> 453
A4: 8 | B4: Informatique & Telecom - Services de réseaux informatiques | C4: 45918 | D4: Services de réseaux informatiques | E4: Informatique & Telecom | F4: Julie GAUJARD | H4: 1 les modifications sont minimes et sans conséquence sur l’achat, | I4: 1 de nombreux fournisseurs possèdent le parc requis, | J4: 5 les manques bloquent l’acte d’achat. | K4: 1 la forte concurrence amène les fournisseurs à s’adapter, | L4: 0 aucune difficulté pour recourir à des produits de substitution, | M4: 5 les achats ne sont que des achats d’urgence par manque de prévisions. | N4: 3 quelques rares fournisseurs imposés peuvent faire l’objet d’une mise en concurrence, | O4: 0 il n’y a pas de limite géographique à l’achat, | P4: 4 le changement de fournisseur est long et fastidieux du fait des procédures administratives, | Q4: 5 le défaut de communication interne est à l’origine d’achats réalisés dans des conditions défavorables. | R4: 1 - Faible | S4: 0 - Nul | T4: 1 - Faible | U4: 1 - Faible | V4: 2 - Modéré | W4: 1 - Faible | X4: 2 - Modéré | Y4: 1 - Faible | Z4: 0 - Nul | AA4: 2 - Modéré | AB4: 0 - Nul | AC4: 2 - Modéré | AD4: 1 - Faible | AE4: 2 - Modéré | AF4: 1 - Faible | AG4: 0 - Nul | AH4: 0 - Sécurisé | AI4: Conserver le fonctionnement d'un marché UGAP | AJ4: 2028 | AK4: Faire ou faire faire (externalisation) | AL4: 4 | AM4: 4.5 | AN4: 6.4 | AO4: 13.6 | AP4: 5.6 | AQ4: 0.8 | AR4: Élément | AS4: sites/DNA948/Lists/Analyse de Portefeuille FINA | AT4: =IFERROR(ROUND(IF(Tableau_query__18[[#This Row],[Sous famille]]<>"",VLOOKUP(Tableau_query__18[[#This Row],[Sous famille]],'A013 TCD'!G:H,2,FALSE),VLOOKUP(Tableau_query__18[[#This Row],[Famille d''achat]],'A013 TCD'!D:E,2,FALSE))/1000,0),"") -> 1352
A5: 9 | B5: Informatique & Telecom - Réseau informatique | C5: 45918 | D5: Réseau informatique | E5: Informatique & Telecom | F5: Laurine AUVRAY | H5: 2 l’achat n’est remis en question que pour quelques pièces, | I5: 1 de nombreux fournisseurs possèdent le parc requis, | J5: 5 les manques bloquent l’acte d’achat. | K5: 1 la forte concurrence amène les fournisseurs à s’adapter, | L5: 3 oblige à n’acheter que des produits de substitution homologués, | M5: 5 les achats ne sont que des achats d’urgence par manque de prévisions. | N5: 0 l’acheteur a toute latitude dans le choix du fournisseur, | O5: 0 il n’y a pas de limite géographique à l’achat, | P5: 4 le changement de fournisseur est long et fastidieux du fait des procédures administratives, | Q5: 5 le défaut de communication interne est à l’origine d’achats réalisés dans des conditions défavorables. | R5: 0 - Nul | S5: 0 - Nul | T5: 1 - Faible | U5: 1 - Faible | V5: 1 - Faible | W5: 0 - Nul | X5: 0 - Nul | Y5: 1 - Faible | Z5: 1 - Faible | AA5: 2 - Modéré | AB5: 0 - Nul | AC5: 1 - Faible | AD5: 1 - Faible | AE5: 1 - Faible | AF5: 0 - Nul | AG5: 2 - Modéré | AH5: 4 - Faible | AI5: Obtenir une expression de besoin du client interne pour savoir si le recours à une centrale d'achat est une option ou s'il faut traiter le dossier en globalité sur un projet de remplacement du matériel obsolète. | AJ5: 2026 | AK5: Faire ou faire faire (externalisation) | AL5: 4 | AM5: 2 | AN5: 9.6 | AO5: 11.2 | AP5: 2.4 | AQ5: 0.8 | AR5: Élément | AS5: sites/DNA948/Lists/Analyse de Portefeuille FINA | AT5: =IFERROR(ROUND(IF(Tableau_query__18[[#This Row],[Sous famille]]<>"",VLOOKUP(Tableau_query__18[[#This Row],[Sous famille]],'A013 TCD'!G:H,2,FALSE),VLOOKUP(Tableau_query__18[[#This Row],[Famille d''achat]],'A013 TCD'!D:E,2,FALSE))/1000,0),"") -> 15
A6: 10 | B6: Informatique & Telecom - Prestations liées aux Progiciels | C6: 45916 | D6: Prestations liées aux Progiciels | E6: Informatique & Telecom | F6: Laurine AUVRAY | H6: 1 les modifications sont minimes et sans conséquence sur l’achat, | I6: 3 entraîne une réduction du nombre de fournisseurs potentiels, | J6: 2 retarde l’achat en l’absence de responsabilité technique, | K6: 1 la forte concurrence amène les fournisseurs à s’adapter, | L6: 5 aucune marge de manœuvre n’est possible. | M6: 1 les prévisions sont relativement satisfaisantes pour couvrir les besoins des acheteurs, | N6: 2 après négociation interne, l’acheteur parvient à qualifier d’autres fournisseurs, | O6: 2 les limites géographiques imposées limitent le choix de fournisseurs, | P6: 4 le changement de fournisseur est long et fastidieux du fait des procédures administratives, | Q6: 1 la communication est suffisante pour les besoins des achats, | R6: 2 - Modéré | S6: 1 - Faible | T6: 2 - Modéré | U6: 1 - Faible | V6: 1 - Faible | W6: 2 - Modéré | X6: 2 - Modéré | Y6: 1 - Faible | Z6: 0 - Nul | AA6: 2 - Modéré | AB6: 0 - Nul | AC6: 0 - Nul | AD6: 1 - Faible | AE6: 1 - Faible | AF6: 0 - Nul | AG6: 0 - Nul | AH6: 1 - Très bon niveau | AI6: Tenter de faire correspondre les dates d'échéance des différents marchés de TMA en cours pour relancer une procédure globale allotie (TMMA, EPM, ORHA, FINA, Portail,...) pour éviter la multiplications des procédures et du temps alloué. | AK6: Faire ou faire faire (externalisation) | AL6: 2 | AM6: 6 | AN6: 9.6 | AO6: 8 | AP6: 8.8 | AQ6: 1.6 | AR6: Élément | AS6: sites/DNA948/Lists/Analyse de Portefeuille FINA | AT6: =IFERROR(ROUND(IF(Tableau_query__18[[#This Row],[Sous famille]]<>"",VLOOKUP(Tableau_query__18[[#This Row],[Sous famille]],'A013 TCD'!G:H,2,FALSE),VLOOKUP(Tableau_query__18[[#This Row],[Famille d''achat]],'A013 TCD'!D:E,2,FALSE))/1000,0),"") -> 3670
A7: 11 | B7: Informatique & Telecom - Prestations liées au matériel et à l'infra | C7: 45918 | D7: Prestations liées au matériel et à l'infra | E7: Informatique & Telecom | F7: Julie GAUJARD | H7: 4 les spécifications sont à l’origine d’une réduction du nombre de fournisseurs potentiel, | I7: 1 de nombreux fournisseurs possèdent le parc requis, | J7: 4 occasionne des achats approximatifs, | K7: 3 entraîne une réduction du nombre de fournisseurs qualifiés, | L7: 5 aucune marge de manœuvre n’est possible. | M7: 5 les achats ne sont que des achats d’urgence par manque de prévisions. | N7: 3 quelques rares fournisseurs imposés peuvent faire l’objet d’une mise en concurrence, | O7: 2 les limites géographiques imposées limitent le choix de fournisseurs, | P7: 4 le changement de fournisseur est long et fastidieux du fait des procédures administratives, | Q7: 5 le défaut de communication interne est à l’origine d’achats réalisés dans des conditions défavorables. | R7: 3 - Important | S7: 0 - Nul | T7: 3 - Important | U7: 1 - Faible | V7: 2 - Modéré | W7: 2 - Modéré | X7: 3 - Important | Y7: 1 - Faible | Z7: 1 - Faible | AA7: 3 - Important | AB7: 0 - Nul | AC7: 1 - Faible | AD7: 2 - Modéré | AE7: 3 - Important | AF7: 0 - Nul | AG7: 0 - Nul | AH7: 2 - Acceptable | AI7: Maintenir la dynamique sur le contrat en cours jusqu'à sa fin. Maintenir le planning de la consultation pour notifier dans les délais. | AJ7: 2025-2026 | AK7: Optimisation du cahier des charges techniques (amélioration des spécifications, cahier des charges fonctionnel) | AL7: 5 | AM7: 7.5 | AN7: 13.6 | AO7: 15.2 | AP7: 6.4 | AQ7: 4.8 | AR7: Élément | AS7: sites/DNA948/Lists/Analyse de Portefeuille FINA | AT7: =IFERROR(ROUND(IF(Tableau_query__18[[#This Row],[Sous famille]]<>"",VLOOKUP(Tableau_query__18[[#This Row],[Sous famille]],'A013 TCD'!G:H,2,FALSE),VLOOKUP(Tableau_query__18[[#This Row],[Famille d''achat]],'A013 TCD'!D:E,2,FALSE))/1000,0),"") -> 4680
A8: 12 | B8: Informatique & Telecom - Poste de travail Informatique | C8: 45916 | D8: Poste de travail Informatique | E8: Informatique & Telecom | F8: Laurine AUVRAY | H8: 2 l’achat n’est remis en question que pour quelques pièces, | I8: 1 de nombreux fournisseurs possèdent le parc requis, | J8: 5 les manques bloquent l’acte d’achat. | K8: 0 la qualité demandée correspond à la moyenne du marché, | L8: 3 oblige à n’acheter que des produits de substitution homologués, | M8: 5 les achats ne sont que des achats d’urgence par manque de prévisions. | N8: 3 quelques rares fournisseurs imposés peuvent faire l’objet d’une mise en concurrence, | O8: 0 il n’y a pas de limite géographique à l’achat, | P8: 4 le changement de fournisseur est long et fastidieux du fait des procédures administratives, | Q8: 5 le défaut de communication interne est à l’origine d’achats réalisés dans des conditions défavorables. | R8: 1 - Faible | S8: 1 - Faible | T8: 1 - Faible | U8: 3 - Important | V8: 1 - Faible | W8: 1 - Faible | X8: 2 - Modéré | Y8: 3 - Important | Z8: 3 - Important | AA8: 3 - Important | AB8: 1 - Faible | AC8: 2 - Modéré | AD8: 2 - Modéré | AE8: 2 - Modéré | AF8: 2 - Modéré | AG8: 4 - Majeur | AH8: 2 - Acceptable | AI8: Recourir à une centrale d'achat pour s'approvisionner car achats simples | AJ8: T4 2025 | AK8: Faire ou faire faire (externalisation) | AL8: 9.5 | AM8: 6.5 | AN8: 8.8 | AO8: 13.6 | AP8: 2.4 | AQ8: 5.6 | AR8: Élément | AS8: sites/DNA948/Lists/Analyse de Portefeuille FINA | AT8: =IFERROR(ROUND(IF(Tableau_query__18[[#This Row],[Sous famille]]<>"",VLOOKUP(Tableau_query__18[[#This Row],[Sous famille]],'A013 TCD'!G:H,2,FALSE),VLOOKUP(Tableau_query__18[[#This Row],[Famille d''achat]],'A013 TCD'!D:E,2,FALSE))/1000,0),"") -> 1445
A9: 13 | B9: Informatique & Telecom - Périphériques et accessoires informatiques | C9: 45916 | D9: Périphériques et accessoires informatiques | E9: Informatique & Telecom | F9: Laurine AUVRAY | H9: 0 elles rejoignent nos propres spécifications, | I9: 0 égale à la moyenne du secteur, | J9: 2 retarde l’achat en l’absence de responsabilité technique, | K9: 0 la qualité demandée correspond à la moyenne du marché, | L9: 0 aucune difficulté pour recourir à des produits de substitution, | M9: 1 les prévisions sont relativement satisfaisantes pour couvrir les besoins des acheteurs, | N9: 0 l’acheteur a toute latitude dans le choix du fournisseur, | O9: 0 il n’y a pas de limite géographique à l’achat, | P9: 1 le circuit administratif retarde les modifications de dossiers d’achat, | Q9: 3 la communication ne permet pas d’anticiper les besoins, | R9: 0 - Nul | S9: 1 - Faible | T9: 2 - Modéré | U9: 2 - Modéré | V9: 1 - Faible | W9: 1 - Faible | X9: 1 - Faible | Y9: 2 - Modéré | Z9: 2 - Modéré | AA9: 2 - Modéré | AB9: 1 - Faible | AC9: 1 - Faible | AD9: 2 - Modéré | AE9: 1 - Faible | AF9: 2 - Modéré | AG9: 3 - Important | AH9: 0 - Sécurisé | AI9: Recourir à une centrale d'achat pour s'approvisionner car achats simples | AJ9: 2025 | AL9: 7 | AM9: 5 | AN9: 1.6 | AO9: 0 | AP9: 0 | AQ9: 0 | AR9: Élément | AS9: sites/DNA948/Lists/Analyse de Portefeuille FINA | AT9: =IFERROR(ROUND(IF(Tableau_query__18[[#This Row],[Sous famille]]<>"",VLOOKUP(Tableau_query__18[[#This Row],[Sous famille]],'A013 TCD'!G:H,2,FALSE),VLOOKUP(Tableau_query__18[[#This Row],[Famille d''achat]],'A013 TCD'!D:E,2,FALSE))/1000,0),"") -> 645
A10: 14 | B10: Informatique & Telecom - Matériels et accessoires de télécommunication | C10: 45918 | D10: Matériels et accessoires de télécommunication | E10: Informatique & Telecom | F10: Julie GAUJARD | AL10: 0 | AM10: 0 | AN10: 0 | AO10: 0 | AP10: 0 | AQ10: 0 | AR10: Élément | AS10: sites/DNA948/Lists/Analyse de Portefeuille FINA | AT10: =IFERROR(ROUND(IF(Tableau_query__18[[#This Row],[Sous famille]]<>"",VLOOKUP(Tableau_query__18[[#This Row],[Sous famille]],'A013 TCD'!G:H,2,FALSE),VLOOKUP(Tableau_query__18[[#This Row],[Famille d''achat]],'A013 TCD'!D:E,2,FALSE))/1000,0),"") -> 34
A11: 15 | B11: Informatique & Telecom - Logiciels | C11: 45916 | D11: Logiciels | E11: Informatique & Telecom | F11: Laurine AUVRAY | H11: 1 les modifications sont minimes et sans conséquence sur l’achat, | I11: 4 oblige à recourir à plusieurs fournisseurs ou sous-traitants, | J11: 3 reporte l’achat à cause d’une refonte nécessaire du dossier technique, | K11: 0 la qualité demandée correspond à la moyenne du marché, | L11: 3 oblige à n’acheter que des produits de substitution homologués, | M11: 5 les achats ne sont que des achats d’urgence par manque de prévisions. | N11: 3 quelques rares fournisseurs imposés peuvent faire l’objet d’une mise en concurrence, | O11: 0 il n’y a pas de limite géographique à l’achat, | P11: 4 le changement de fournisseur est long et fastidieux du fait des procédures administratives, | Q11: 4 le défaut de communication interne crée un frein à l’étude du marché, | R11: 0 - Nul | S11: 0 - Nul | T11: 0 - Nul | U11: 0 - Nul | V11: 1 - Faible | W11: 0 - Nul | X11: 1 - Faible | Y11: 2 - Modéré | Z11: 2 - Modéré | AA11: 2 - Modéré | AB11: 0 - Nul | AC11: 1 - Faible | AD11: 1 - Faible | AE11: 1 - Faible | AF11: 0 - Nul | AG11: 0 - Nul | AH11: 0 - Sécurisé | AI11: Obtenir une liste complète des besoins fournie par la DSI et la DII | AJ11: T3 2027 | AL11: 3.5 | AM11: 2 | AN11: 8.8 | AO11: 0 | AP11: 2.4 | AQ11: 1.6 | AR11: Élément | AS11: sites/DNA948/Lists/Analyse de Portefeuille FINA | AT11: =IFERROR(ROUND(IF(Tableau_query__18[[#This Row],[Sous famille]]<>"",VLOOKUP(Tableau_query__18[[#This Row],[Sous famille]],'A013 TCD'!G:H,2,FALSE),VLOOKUP(Tableau_query__18[[#This Row],[Famille d''achat]],'A013 TCD'!D:E,2,FALSE))/1000,0),"") -> 6669
A12: 16 | B12: Informatique & Telecom - E-learning | C12: 45918 | D12: E-learning | E12: Informatique & Telecom | F12: Laurine AUVRAY | H12: 4 les spécifications sont à l’origine d’une réduction du nombre de fournisseurs potentiel, | I12: 3 entraîne une réduction du nombre de fournisseurs potentiels, | J12: 4 occasionne des achats approximatifs, | K12: 4 est à l’origine d’un marché fermé (1 acheteur et 1 vendeur), | L12: 4 oblige à négocier âprement avec le fabricant retenu par les services techniques, | M12: 1 les prévisions sont relativement satisfaisantes pour couvrir les besoins des acheteurs, | N12: 0 l’acheteur a toute latitude dans le choix du fournisseur, | O12: 1 les limites géographiques imposées n’entraînent pas de frein à l’achat, | P12: 4 le changement de fournisseur est long et fastidieux du fait des procédures administratives, | Q12: 2 les contacts sont rares avec les services non directement concernés par l’acte d’achat, | R12: 3 - Important | S12: 2 - Modéré | T12: 2 - Modéré | U12: 1 - Faible | V12: 1 - Faible | W12: 2 - Modéré | X12: 2 - Modéré | Y12: 2 - Modéré | Z12: 1 - Faible | AA12: 2 - Modéré | AB12: 2 - Modéré | AC12: 0 - Nul | AD12: 1 - Faible | AE12: 1 - Faible | AF12: 1 - Faible | AG12: 1 - Faible | AH12: 0 - Sécurisé | AI12: Mieux travailler le cahier des charges par le client interne pour optimiser la concurrence | AJ12: 2028 | AK12: Optimisation du cahier des charges techniques (amélioration des spécifications, cahier des charges fonctionnel) | AL12: 4.5 | AM12: 7.5 | AN12: 15.2 | AO12: 6.4 | AP12: 4 | AQ12: 1.6 | AR12: Élément | AS12: sites/DNA948/Lists/Analyse de Portefeuille FINA | AT12: =IFERROR(ROUND(IF(Tableau_query__18[[#This Row],[Sous famille]]<>"",VLOOKUP(Tableau_query__18[[#This Row],[Sous famille]],'A013 TCD'!G:H,2,FALSE),VLOOKUP(Tableau_query__18[[#This Row],[Famille d''achat]],'A013 TCD'!D:E,2,FALSE))/1000,0),"") -> 117
A13: 17 | B13: Informatique & Telecom - Datacenter et Cloud | C13: 45918 | D13: Datacenter et Cloud | E13: Informatique & Telecom | F13: Julie GAUJARD | H13: 4 les spécifications sont à l’origine d’une réduction du nombre de fournisseurs potentiel, | I13: 1 de nombreux fournisseurs possèdent le parc requis, | J13: 4 occasionne des achats approximatifs, | K13: 3 entraîne une réduction du nombre de fournisseurs qualifiés, | L13: 5 aucune marge de manœuvre n’est possible. | M13: 5 les achats ne sont que des achats d’urgence par manque de prévisions. | N13: 3 quelques rares fournisseurs imposés peuvent faire l’objet d’une mise en concurrence, | O13: 2 les limites géographiques imposées limitent le choix de fournisseurs, | P13: 4 le changement de fournisseur est long et fastidieux du fait des procédures administratives, | Q13: 5 le défaut de communication interne est à l’origine d’achats réalisés dans des conditions défavorables. | R13: 4 - Majeur | S13: 0 - Nul | T13: 3 - Important | U13: 1 - Faible | V13: 2 - Modéré | W13: 4 - Majeur | X13: 2 - Modéré | Y13: 1 - Faible | Z13: 1 - Faible | AA13: 3 - Important | AB13: 0 - Nul | AC13: 1 - Faible | AD13: 2 - Modéré | AE13: 3 - Important | AF13: 0 - Nul | AG13: 0 - Nul | AH13: 2 - Acceptable | AI13: Maintenir la dynamique sur le contrat en cours jusqu'à sa fin. Maintenir le planning de la consultation pour notifier dans les délais. | AJ13: 2025-2026 | AK13: Optimisation du cahier des charges techniques (amélioration des spécifications, cahier des charges fonctionnel) | AL13: 5 | AM13: 8.5 | AN13: 13.6 | AO13: 15.2 | AP13: 6.4 | AQ13: 3.2 | AR13: Élément | AS13: sites/DNA948/Lists/Analyse de Portefeuille FINA | AT13: =IFERROR(ROUND(IF(Tableau_query__18[[#This Row],[Sous famille]]<>"",VLOOKUP(Tableau_query__18[[#This Row],[Sous famille]],'A013 TCD'!G:H,2,FALSE),VLOOKUP(Tableau_query__18[[#This Row],[Famille d''achat]],'A013 TCD'!D:E,2,FALSE))/1000,0),"") -> 3582
A14: 18 | B14: Informatique & Telecom - Conseil et audit | C14: 45916 | D14: Conseil et audit | E14: Informatique & Telecom | F14: Laurine AUVRAY | H14: 1 les modifications sont minimes et sans conséquence sur l’achat, | I14: 1 de nombreux fournisseurs possèdent le parc requis, | J14: 4 occasionne des achats approximatifs, | K14: 1 la forte concurrence amène les fournisseurs à s’adapter, | L14: 0 aucune difficulté pour recourir à des produits de substitution, | M14: 4 les prévisions n’existent qu’à court terme et ont donc un impact moindre auprès des fournisseurs, | N14: 0 l’acheteur a toute latitude dans le choix du fournisseur, | O14: 2 les limites géographiques imposées limitent le choix de fournisseurs, | P14: 4 le changement de fournisseur est long et fastidieux du fait des procédures administratives, | Q14: 3 la communication ne permet pas d’anticiper les besoins, | R14: 0 - Nul | S14: 0 - Nul | T14: 2 - Modéré | U14: 0 - Nul | V14: 3 - Important | W14: 0 - Nul | X14: 2 - Modéré | Y14: 3 - Important | Z14: 1 - Faible | AA14: 2 - Modéré | AB14: 0 - Nul | AC14: 1 - Faible | AD14: 0 - Nul | AE14: 2 - Modéré | AF14: 0 - Nul | AG14: 0 - Nul | AH14: 1 - Très bon niveau | AI14: Prévoir le type de renouvellement (subséquents avec classement, remise en concurrence...?). Le client interne est-il capable de nous fournir une programmation des besoins à venir. | AJ14: T2 2026 | AL14: 3 | AM14: 5 | AN14: 5.6 | AO14: 0 | AP14: 0 | AQ14: 0 | AR14: Élément | AS14: sites/DNA948/Lists/Analyse de Portefeuille FINA | AT14: =IFERROR(ROUND(IF(Tableau_query__18[[#This Row],[Sous famille]]<>"",VLOOKUP(Tableau_query__18[[#This Row],[Sous famille]],'A013 TCD'!G:H,2,FALSE),VLOOKUP(Tableau_query__18[[#This Row],[Famille d''achat]],'A013 TCD'!D:E,2,FALSE))/1000,0),"") -> 4524
A15: 19 | B15: Matériels - Solier | C15: 45938 | D15: Solier | E15: Matériels | F15: Jérôme CORTES | AL15: 0 | AM15: 0 | AN15: 0 | AO15: 0 | AP15: 0 | AQ15: 0 | AR15: Élément | AS15: sites/DNA948/Lists/Analyse de Portefeuille FINA | AT15: =IFERROR(ROUND(IF(Tableau_query__18[[#This Row],[Sous famille]]<>"",VLOOKUP(Tableau_query__18[[#This Row],[Sous famille]],'A013 TCD'!G:H,2,FALSE),VLOOKUP(Tableau_query__18[[#This Row],[Famille d''achat]],'A013 TCD'!D:E,2,FALSE))/1000,0),"") -> 241
A16: 20 | B16: Matériels - Quincaillerie d assemblage | D16: Quincaillerie d assemblage | E16: Matériels | F16: Laurent AGBOTON | AR16: Élément | AS16: sites/DNA948/Lists/Analyse de Portefeuille FINA | AT16: =IFERROR(ROUND(IF(Tableau_query__18[[#This Row],[Sous famille]]<>"",VLOOKUP(Tableau_query__18[[#This Row],[Sous famille]],'A013 TCD'!G:H,2,FALSE),VLOOKUP(Tableau_query__18[[#This Row],[Famille d''achat]],'A013 TCD'!D:E,2,FALSE))/1000,0),"") -> 140
A17: 21 | B17: Matériels - Quincaillerie d ameublement | D17: Quincaillerie d ameublement | E17: Matériels | F17: Laurent AGBOTON | AR17: Élément | AS17: sites/DNA948/Lists/Analyse de Portefeuille FINA | AT17: =IFERROR(ROUND(IF(Tableau_query__18[[#This Row],[Sous famille]]<>"",VLOOKUP(Tableau_query__18[[#This Row],[Sous famille]],'A013 TCD'!G:H,2,FALSE),VLOOKUP(Tableau_query__18[[#This Row],[Famille d''achat]],'A013 TCD'!D:E,2,FALSE))/1000,0),"") -> 243
A18: 22 | B18: Matériels - Produits métallurgiques hors bâtiment | C18: 45979 | D18: Produits métallurgiques hors bâtiment | E18: Matériels | F18: Guy HORNUNG | H18: 1 les modifications sont minimes et sans conséquence sur l’achat, | I18: 3 entraîne une réduction du nombre de fournisseurs potentiels, | J18: 1 les précisions nécessaires au fournisseur peuvent être obtenues sans difficulté, | L18: 5 aucune marge de manœuvre n’est possible. | M18: 0 les prévisions à moyen et long terme sont fiables, | N18: 0 l’acheteur a toute latitude dans le choix du fournisseur, | O18: 0 il n’y a pas de limite géographique à l’achat, | P18: 0 pas de lourdeur administrative, | Q18: 1 la communication est suffisante pour les besoins des achats, | T18: 2 - Modéré | U18: 2 - Modéré | V18: 0 - Nul | X18: 1 - Faible | Y18: 1 - Faible | Z18: 1 - Faible | AC18: 2 - Modéré | AD18: 1 - Faible | AE18: 3 - Important | AG18: 1 - Faible | AH18: 0 - Sécurisé | AI18: Lancement d'un AO en regroupant les Produits métallurgiques du Bâtiment | AJ18: 2028/2029 | AK18: Conception à coût objectif (CCO) | AL18: 4 | AM18: 3 | AN18: 8 | AO18: 0.8 | AP18: 4 | AQ18: 0 | AR18: Élément | AS18: sites/DNA948/Lists/Analyse de Portefeuille FINA | AT18: =IFERROR(ROUND(IF(Tableau_query__18[[#This Row],[Sous famille]]<>"",VLOOKUP(Tableau_query__18[[#This Row],[Sous famille]],'A013 TCD'!G:H,2,FALSE),VLOOKUP(Tableau_query__18[[#This Row],[Famille d''achat]],'A013 TCD'!D:E,2,FALSE))/1000,0),"") -> 738
A19: 23 | B19: Matériels - Produits d'hygiène et de nettoyage | D19: Produits d'hygiène et de nettoyage | E19: Matériels | F19: Laurent AGBOTON | AR19: Élément | AS19: sites/DNA948/Lists/Analyse de Portefeuille FINA | AT19: =IFERROR(ROUND(IF(Tableau_query__18[[#This Row],[Sous famille]]<>"",VLOOKUP(Tableau_query__18[[#This Row],[Sous famille]],'A013 TCD'!G:H,2,FALSE),VLOOKUP(Tableau_query__18[[#This Row],[Famille d''achat]],'A013 TCD'!D:E,2,FALSE))/1000,0),"") -> 231
A20: 24 | B20: Matériels - Produit métallurgique du bâtiment | D20: Produit métallurgique du bâtiment | E20: Matériels | F20: Jérôme CORTES | AL20: 0 | AM20: 0 | AN20: 0 | AO20: 0 | AP20: 0 | AQ20: 0 | AR20: Élément | AS20: sites/DNA948/Lists/Analyse de Portefeuille FINA | AT20: =IFERROR(ROUND(IF(Tableau_query__18[[#This Row],[Sous famille]]<>"",VLOOKUP(Tableau_query__18[[#This Row],[Sous famille]],'A013 TCD'!G:H,2,FALSE),VLOOKUP(Tableau_query__18[[#This Row],[Famille d''achat]],'A013 TCD'!D:E,2,FALSE))/1000,0),"") -> 65
A21: 25 | B21: Matériels - Plaquiste | D21: Plaquiste | E21: Matériels | F21: Jérôme CORTES | AR21: Élément | AS21: sites/DNA948/Lists/Analyse de Portefeuille FINA | AT21: =IFERROR(ROUND(IF(Tableau_query__18[[#This Row],[Sous famille]]<>"",VLOOKUP(Tableau_query__18[[#This Row],[Sous famille]],'A013 TCD'!G:H,2,FALSE),VLOOKUP(Tableau_query__18[[#This Row],[Famille d''achat]],'A013 TCD'!D:E,2,FALSE))/1000,0),"") -> 988
A22: 26 | B22: Matériels - Peinture et revêtements muraux | D22: Peinture et revêtements muraux | E22: Matériels | F22: Jérôme CORTES | AR22: Élément | AS22: sites/DNA948/Lists/Analyse de Portefeuille FINA | AT22: =IFERROR(ROUND(IF(Tableau_query__18[[#This Row],[Sous famille]]<>"",VLOOKUP(Tableau_query__18[[#This Row],[Sous famille]],'A013 TCD'!G:H,2,FALSE),VLOOKUP(Tableau_query__18[[#This Row],[Famille d''achat]],'A013 TCD'!D:E,2,FALSE))/1000,0),"") -> 570
A23: 27 | B23: Matériels - Outils pneumatiques | D23: Outils pneumatiques | E23: Matériels | F23: Laurent AGBOTON | AR23: Élément | AS23: sites/DNA948/Lists/Analyse de Portefeuille FINA | AT23: =IFERROR(ROUND(IF(Tableau_query__18[[#This Row],[Sous famille]]<>"",VLOOKUP(Tableau_query__18[[#This Row],[Sous famille]],'A013 TCD'!G:H,2,FALSE),VLOOKUP(Tableau_query__18[[#This Row],[Famille d''achat]],'A013 TCD'!D:E,2,FALSE))/1000,0),"") -> 11
A24: 28 | B24: Matériels - Outils coupants | D24: Outils coupants | E24: Matériels | F24: Laurent AGBOTON | AR24: Élément | AS24: sites/DNA948/Lists/Analyse de Portefeuille FINA | AT24: =IFERROR(ROUND(IF(Tableau_query__18[[#This Row],[Sous famille]]<>"",VLOOKUP(Tableau_query__18[[#This Row],[Sous famille]],'A013 TCD'!G:H,2,FALSE),VLOOKUP(Tableau_query__18[[#This Row],[Famille d''achat]],'A013 TCD'!D:E,2,FALSE))/1000,0),"") -> 108
A25: 29 | B25: Matériels - Outillage à mains | D25: Outillage à mains | E25: Matériels | F25: Laurent AGBOTON | AR25: Élément | AS25: sites/DNA948/Lists/Analyse de Portefeuille FINA | AT25: =IFERROR(ROUND(IF(Tableau_query__18[[#This Row],[Sous famille]]<>"",VLOOKUP(Tableau_query__18[[#This Row],[Sous famille]],'A013 TCD'!G:H,2,FALSE),VLOOKUP(Tableau_query__18[[#This Row],[Famille d''achat]],'A013 TCD'!D:E,2,FALSE))/1000,0),"") -> 673
A26: 30 | B26: Matériels - Monteurs de réseau | D26: Monteurs de réseau | E26: Matériels | F26: Jérôme CORTES | AR26: Élément | AS26: sites/DNA948/Lists/Analyse de Portefeuille FINA | AT26: =IFERROR(ROUND(IF(Tableau_query__18[[#This Row],[Sous famille]]<>"",VLOOKUP(Tableau_query__18[[#This Row],[Sous famille]],'A013 TCD'!G:H,2,FALSE),VLOOKUP(Tableau_query__18[[#This Row],[Famille d''achat]],'A013 TCD'!D:E,2,FALSE))/1000,0),"") -> 269
A27: 31 | B27: Matériels - Mobilier de bureau d'accueil et accessoire | D27: Mobilier de bureau d'accueil et accessoire | E27: Matériels | F27: Laurent AGBOTON | AR27: Élément | AS27: sites/DNA948/Lists/Analyse de Portefeuille FINA | AT27: =IFERROR(ROUND(IF(Tableau_query__18[[#This Row],[Sous famille]]<>"",VLOOKUP(Tableau_query__18[[#This Row],[Sous famille]],'A013 TCD'!G:H,2,FALSE),VLOOKUP(Tableau_query__18[[#This Row],[Famille d''achat]],'A013 TCD'!D:E,2,FALSE))/1000,0),"") -> 482
A28: 32 | B28: Matériels - Matériels de surveillance | D28: Matériels de surveillance | E28: Matériels | F28: Jérôme CORTES | AR28: Élément | AS28: sites/DNA948/Lists/Analyse de Portefeuille FINA | AT28: =IFERROR(ROUND(IF(Tableau_query__18[[#This Row],[Sous famille]]<>"",VLOOKUP(Tableau_query__18[[#This Row],[Sous famille]],'A013 TCD'!G:H,2,FALSE),VLOOKUP(Tableau_query__18[[#This Row],[Famille d''achat]],'A013 TCD'!D:E,2,FALSE))/1000,0),"") -> 293
A29: 33 | B29: Matériels - Maçonnerie VRD | D29: Maçonnerie VRD | E29: Matériels | F29: Jérôme CORTES | AR29: Élément | AS29: sites/DNA948/Lists/Analyse de Portefeuille FINA | AT29: =IFERROR(ROUND(IF(Tableau_query__18[[#This Row],[Sous famille]]<>"",VLOOKUP(Tableau_query__18[[#This Row],[Sous famille]],'A013 TCD'!G:H,2,FALSE),VLOOKUP(Tableau_query__18[[#This Row],[Famille d''achat]],'A013 TCD'!D:E,2,FALSE))/1000,0),"") -> 1262
A30: 34 | B30: Matériels - Isolation Thermique par l'Extérieur | D30: Isolation Thermique par l'Extérieur | E30: Matériels | F30: Jérôme CORTES | AR30: Élément | AS30: sites/DNA948/Lists/Analyse de Portefeuille FINA | AT30: =IFERROR(ROUND(IF(Tableau_query__18[[#This Row],[Sous famille]]<>"",VLOOKUP(Tableau_query__18[[#This Row],[Sous famille]],'A013 TCD'!G:H,2,FALSE),VLOOKUP(Tableau_query__18[[#This Row],[Famille d''achat]],'A013 TCD'!D:E,2,FALSE))/1000,0),"") -> 125
A31: 35 | B31: Matériels - Gaz industriels | D31: Gaz industriels | E31: Matériels | F31: Guy HORNUNG | AR31: Élément | AS31: sites/DNA948/Lists/Analyse de Portefeuille FINA | AT31: =IFERROR(ROUND(IF(Tableau_query__18[[#This Row],[Sous famille]]<>"",VLOOKUP(Tableau_query__18[[#This Row],[Sous famille]],'A013 TCD'!G:H,2,FALSE),VLOOKUP(Tableau_query__18[[#This Row],[Famille d''achat]],'A013 TCD'!D:E,2,FALSE))/1000,0),"") -> 1265
A32: 36 | B32: Matériels - Fournitures nautiques et aéronautiques | D32: Fournitures nautiques et aéronautiques | E32: Matériels | F32: Guy HORNUNG | AR32: Élément | AS32: sites/DNA948/Lists/Analyse de Portefeuille FINA | AT32: =IFERROR(ROUND(IF(Tableau_query__18[[#This Row],[Sous famille]]<>"",VLOOKUP(Tableau_query__18[[#This Row],[Sous famille]],'A013 TCD'!G:H,2,FALSE),VLOOKUP(Tableau_query__18[[#This Row],[Famille d''achat]],'A013 TCD'!D:E,2,FALSE))/1000,0),"") -> 224
... A59: 63 | B59: Prestations - Véhicule de service et de fonction | D59: Véhicule de service et de fonction | E59: Prestations | F59: Stéphane DELATOUR | AR59: Élément | AS59: sites/DNA948/Lists/Analyse de Portefeuille FINA | AT59: =IFERROR(ROUND(IF(Tableau_query__18[[#This Row],[Sous famille]]<>"",VLOOKUP(Tableau_query__18[[#This Row],[Sous famille]],'A013 TCD'!G:H,2,FALSE),VLOOKUP(Tableau_query__18[[#This Row],[Famille d''achat]],'A013 TCD'!D:E,2,FALSE))/1000,0),"") -> 7437
A60: 64 | B60: Prestations - Transport de personnes | C60: 46030 | D60: Transport de personnes | E60: Prestations | F60: Cindy CHUNE | H60: 1 les modifications sont minimes et sans conséquence sur l’achat, | I60: 1 de nombreux fournisseurs possèdent le parc requis, | J60: 1 les précisions nécessaires au fournisseur peuvent être obtenues sans difficulté, | K60: 0 la qualité demandée correspond à la moyenne du marché, | L60: 0 aucune difficulté pour recourir à des produits de substitution, | M60: 1 les prévisions sont relativement satisfaisantes pour couvrir les besoins des acheteurs, | N60: 0 l’acheteur a toute latitude dans le choix du fournisseur, | O60: 2 les limites géographiques imposées limitent le choix de fournisseurs, | P60: 0 pas de lourdeur administrative, | Q60: 1 la communication est suffisante pour les besoins des achats, | R60: 1 - Faible | S60: 0 - Nul | T60: 1 - Faible | U60: 1 - Faible | V60: 0 - Nul | W60: 0 - Nul | X60: 3 - Important | Y60: 3 - Important | Z60: 3 - Important | AA60: 2 - Modéré | AB60: 0 - Nul | AC60: 0 - Nul | AD60: 2 - Modéré | AE60: 1 - Faible | AF60: 1 - Faible | AG60: 1 - Faible | AH60: 0 - Sécurisé | AI60: Le Marché CAP 5 couvre 38% sur 80 000€ ed dépenses en 2025 (location véhicule courte durée ou transport en commun avion,train,..). Les autres dépenses sont des locations de bus avec chauffeur pour transport de stagiaires (40 000€ environ). Le nouveaux seuil du MAPA étant porté à 60 000€, il ne sera pas réalisé de marché spécifique . | AL60: 4.5 | AM60: 4.5 | AN60: 2.4 | AO60: 3.2 | AP60: 0.8 | AQ60: 0 | AR60: Élément | AS60: sites/DNA948/Lists/Analyse de Portefeuille FINA | AT60: =IFERROR(ROUND(IF(Tableau_query__18[[#This Row],[Sous famille]]<>"",VLOOKUP(Tableau_query__18[[#This Row],[Sous famille]],'A013 TCD'!G:H,2,FALSE),VLOOKUP(Tableau_query__18[[#This Row],[Famille d''achat]],'A013 TCD'!D:E,2,FALSE))/1000,0),"") -> 95
A61: 65 | B61: Prestations - Signalétique | D61: Signalétique | E61: Prestations | F61: Smahan EL MALAH | AR61: Élément | AS61: sites/DNA948/Lists/Analyse de Portefeuille FINA | AT61: =IFERROR(ROUND(IF(Tableau_query__18[[#This Row],[Sous famille]]<>"",VLOOKUP(Tableau_query__18[[#This Row],[Sous famille]],'A013 TCD'!G:H,2,FALSE),VLOOKUP(Tableau_query__18[[#This Row],[Famille d''achat]],'A013 TCD'!D:E,2,FALSE))/1000,0),"") -> 186
A62: 66 | B62: Prestations - Services liés aux déchets et ordures | C62: 45958 | D62: Services liés aux déchets et ordures | E62: Prestations | F62: Karine FANTINI | H62: 3 les spécifications obligent à des renégociations avec les fournisseurs, | I62: 1 de nombreux fournisseurs possèdent le parc requis, | J62: 4 occasionne des achats approximatifs, | L62: 5 aucune marge de manœuvre n’est possible. | M62: 3 les prévisions sont aléatoires, ce qui est préjudiciable aux négociations, | N62: 0 l’acheteur a toute latitude dans le choix du fournisseur, | O62: 2 les limites géographiques imposées limitent le choix de fournisseurs, | P62: 2 les lourdeurs administratives occasionnent des retards de paiement des fournisseurs, | Q62: 1 la communication est suffisante pour les besoins des achats, | T62: 2 - Modéré | U62: 2 - Modéré | V62: 3 - Important | X62: 3 - Important | Y62: 1 - Faible | Z62: 3 - Important | AC62: 3 - Important | AD62: 1 - Faible | AE62: 3 - Important | AG62: 5 - Extrême | AH62: 1 - Très bon niveau | AI62: Revoir le BPU et désignation d'articles obsolescents. Fiabiliser les DQE. Revoir l'allotissement : actuellement en grandes régions, génère de la sous-traitance et des coûts de transport plus élevés. Prévoir un allotissement en mode "territoire" (Regroupement de plusieurs Sites Afpa au plus près des centres de tri), surtout pour les déchets spéciaux | AJ62: 2027 S1 | AL62: 0 | AM62: 5.5 | AN62: 10.4 | AO62: 0 | AP62: 4 | AQ62: 0 | AR62: Élément | AS62: sites/DNA948/Lists/Analyse de Portefeuille FINA | AT62: =IFERROR(ROUND(IF(Tableau_query__18[[#This Row],[Sous famille]]<>"",VLOOKUP(Tableau_query__18[[#This Row],[Sous famille]],'A013 TCD'!G:H,2,FALSE),VLOOKUP(Tableau_query__18[[#This Row],[Famille d''achat]],'A013 TCD'!D:E,2,FALSE))/1000,0),"") -> 3184
A63: 67 | B63: Prestations - Services financiers et d'assurances | C63: 46106 | D63: Services financiers et d'assurances | E63: Prestations | F63: Nathalie CORMIER | H63: 3 les spécifications obligent à des renégociations avec les fournisseurs, | I63: 3 entraîne une réduction du nombre de fournisseurs potentiels, | J63: 2 retarde l’achat en l’absence de responsabilité technique, | K63: 3 entraîne une réduction du nombre de fournisseurs qualifiés, | L63: 5 aucune marge de manœuvre n’est possible. | M63: 1 les prévisions sont relativement satisfaisantes pour couvrir les besoins des acheteurs, | N63: 1 les impositions correspondent au meilleur choix, | O63: 1 les limites géographiques imposées n’entraînent pas de frein à l’achat, | P63: 3 le circuit administratif engendre des litiges avec les fournisseurs, | Q63: 2 les contacts sont rares avec les services non directement concernés par l’acte d’achat, | R63: 2 - Modéré | S63: 2 - Modéré | T63: 0 - Nul | U63: 3 - Important | V63: 2 - Modéré | W63: 0 - Nul | X63: 1 - Faible | Y63: 1 - Faible | Z63: 1 - Faible | AA63: 1 - Faible | AC63: 1 - Faible | AD63: 1 - Faible | AE63: 1 - Faible | AF63: 1 - Faible | AG63: 1 - Faible | AH63: 1 - Très bon niveau | AI63: 2026-2027 :Remise en concurrence des marchés d'assurances qui couvrent 97% du CA. Les 3 % restants correspponde aux franchises qui sont directement payés aux garagistes. Ana lyse d'opportunité pour envisager de faire appel au RESAH (courtieravec une mission de recherche de solutions assurantielles et UGAP (assurance voiture) | AJ63: 2027 | AK63: Faire ou faire faire (externalisation) | AL63: 0 | AM63: 0 | AN63: 12.8 | AO63: 6.4 | AP63: 2.4 | AQ63: 8.8 | AR63: Élément | AS63: sites/DNA948/Lists/Analyse de Portefeuille FINA | AT63: =IFERROR(ROUND(IF(Tableau_query__18[[#This Row],[Sous famille]]<>"",VLOOKUP(Tableau_query__18[[#This Row],[Sous famille]],'A013 TCD'!G:H,2,FALSE),VLOOKUP(Tableau_query__18[[#This Row],[Famille d''achat]],'A013 TCD'!D:E,2,FALSE))/1000,0),"") -> 2485
A64: 68 | B64: Prestations - Services divers | D64: Services divers | E64: Prestations | F64: Smahan EL MALAH | AR64: Élément | AS64: sites/DNA948/Lists/Analyse de Portefeuille FINA | AT64: =IFERROR(ROUND(IF(Tableau_query__18[[#This Row],[Sous famille]]<>"",VLOOKUP(Tableau_query__18[[#This Row],[Sous famille]],'A013 TCD'!G:H,2,FALSE),VLOOKUP(Tableau_query__18[[#This Row],[Famille d''achat]],'A013 TCD'!D:E,2,FALSE))/1000,0),"") -> 5
A65: 69 | B65: Prestations - Services d'Impression, de publication et services connexes | C65: 46111 | D65: Services d'Impression, de publication et services connexes | E65: Prestations | F65: Cindy CHUNE | H65: 4 les spécifications sont à l’origine d’une réduction du nombre de fournisseurs potentiel, | I65: 1 de nombreux fournisseurs possèdent le parc requis, | J65: 2 retarde l’achat en l’absence de responsabilité technique, | K65: 0 la qualité demandée correspond à la moyenne du marché, | L65: 0 aucune difficulté pour recourir à des produits de substitution, | M65: 4 les prévisions n’existent qu’à court terme et ont donc un impact moindre auprès des fournisseurs, | N65: 2 après négociation interne, l’acheteur parvient à qualifier d’autres fournisseurs, | O65: 1 les limites géographiques imposées n’entraînent pas de frein à l’achat, | P65: 1 le circuit administratif retarde les modifications de dossiers d’achat, | Q65: 4 le défaut de communication interne crée un frein à l’étude du marché, | R65: 1 - Faible | S65: 0 - Nul | T65: 1 - Faible | U65: 1 - Faible | V65: 0 - Nul | W65: 1 - Faible | X65: 3 - Important | Y65: 3 - Important | Z65: 2 - Modéré | AA65: 3 - Important | AB65: 2 - Modéré | AC65: 2 - Modéré | AD65: 2 - Modéré | AE65: 2 - Modéré | AF65: 3 - Important | AG65: 2 - Modéré | AH65: 5 - Critique | AI65: Mettre en place un marché multi service pour couvrir l'ensemble du processus impressions et services connexes comme la numérisation, le façonnage, etc. | AJ65: 2026 | AK65: Harmonisation, standardisation de l'achat | AL65: 9 | AM65: 5 | AN65: 5.6 | AO65: 9.6 | AP65: 1.6 | AQ65: 0 | AR65: Élément | AS65: sites/DNA948/Lists/Analyse de Portefeuille FINA | AT65: =IFERROR(ROUND(IF(Tableau_query__18[[#This Row],[Sous famille]]<>"",VLOOKUP(Tableau_query__18[[#This Row],[Sous famille]],'A013 TCD'!G:H,2,FALSE),VLOOKUP(Tableau_query__18[[#This Row],[Famille d''achat]],'A013 TCD'!D:E,2,FALSE))/1000,0),"") -> 111
A66: 70 | B66: Prestations - Services d'entretien d'ascenseurs et de monte-charges portes et portails | C66: 45959 | D66: Services d'entretien d'ascenseurs et de monte-charges | E66: Prestations | F66: Karine FANTINI | H66: 0 elles rejoignent nos propres spécifications, | I66: 1 de nombreux fournisseurs possèdent le parc requis, | J66: 1 les précisions nécessaires au fournisseur peuvent être obtenues sans difficulté, | L66: 5 aucune marge de manœuvre n’est possible. | M66: 0 les prévisions à moyen et long terme sont fiables, | N66: 0 l’acheteur a toute latitude dans le choix du fournisseur, | O66: 1 les limites géographiques imposées n’entraînent pas de frein à l’achat, | P66: 2 les lourdeurs administratives occasionnent des retards de paiement des fournisseurs, | Q66: 1 la communication est suffisante pour les besoins des achats, | T66: 1 - Faible | U66: 2 - Modéré | V66: 1 - Faible | X66: 3 - Important | Y66: 0 - Nul | Z66: 0 - Nul | AC66: 3 - Important | AD66: 1 - Faible | AE66: 2 - Modéré | AG66: 1 - Faible | AH66: 0 - Sécurisé | AI66: Sourcing afin d'assurer un maximum de candidatures lors de la consultation. Optimiser la passation de commandes groupées et le plus tôt possible dans l'année afin de garantir la planification des interventions de maintenance. Participer à des salons prof. | AJ66: 2028 S2 | AK66: Sourcing fournisseurs / benchmark (connaissance offre du marché, connaissance structures de coûts) | AL66: 3.5 | AM66: 3.5 | AN66: 5.6 | AO66: 3.2 | AP66: 0.8 | AQ66: 0 | AR66: Élément | AS66: sites/DNA948/Lists/Analyse de Portefeuille FINA | AT66: =IFERROR(ROUND(IF(Tableau_query__18[[#This Row],[Sous famille]]<>"",VLOOKUP(Tableau_query__18[[#This Row],[Sous famille]],'A013 TCD'!G:H,2,FALSE),VLOOKUP(Tableau_query__18[[#This Row],[Famille d''achat]],'A013 TCD'!D:E,2,FALSE))/1000,0),"") -> 216
...

Sheet A013 TCD
A1: Segment | D1: Famille | G1: Sous-famille
A3: Étiquettes de lignes | B3: Somme de Montant commandé HT | D3: Étiquettes de lignes | E3: Somme de Montant commandé HT | G3: Étiquettes de lignes | H3: Somme de Montant commandé HT
A4: Informatique & Telecom | B4: 29013541 | D4: Aménagements intérieurs | E4: 2432389 | G4: Abonnement aux services de transport en commun | H4: 14769.96
A5: Matériels | B5: 23159711 | D5: Annonces et insertions | E5: 1080907.8 | G5: Abonnements revues supports dématérialisés | H5: 179917.8
A6: Prestations | B6: 1.3594749e+08 | D6: Audits et certifications | E6: 281863.85 | G6: Abonnements revues supports papier ou mixte | H6: 487500.24
A7: Travaux | B7: 40798700 | D7: Banchage | E7: 10505.261 | G7: Abrasifs | H7: 60576.764
A8: Total général | B8: 2.2891944e+08 | D8: Carburant non routier | E8: 93748.593 | G8: Absorbants et dépolluants | H8: 9198.16
D9: Carreleur | E9: 338311.9 | G9: Accès à distance et droit utilisation e-learning | H9: 102164.75
D10: Centre d'appel | E10: 1849742.1 | G10: Accessoires Carrosserie | H10: 122366.98
D11: Conseil et audit | E11: 4524370.6 | G11: Accessoires Chauffage et refroidissement | H11: 24940.38
D12: Construction modulaire | E12: 9376.12 | G12: Accessoires Couvreur zingueur | H12: 25033.956
D13: Contrôle reglementaire | E13: 1091829.4 | G13: Accessoires Cycle | H13: 8516.37
D14: Contrôle technique | E14: 16158.314 | G14: Accessoires de cloture | H14: 1600.62
D15: Courrier et affranchissements | E15: 2307644.1 | G15: Accessoires de finition | H15: 47422.068
D16: Couvreur-Zingueur | E16: 170374.17 | G16: Accessoires de finition pour les revêtements muraux | H16: 428.16
D17: Datacenter et Cloud | E17: 3581502 | G17: Accessoires de loisirs | H17: 22575.26
D18: Droits d'auteurs et prestations diverses | E18: 84671.48 | G18: Accessoires Echappement | H18: 413.41
D19: E-learning | E19: 117111.49 | G19: Accessoires Electricité | H19: 109218.43
D20: Electroportatifs | E20: 370096.52 | G20: Accessoires électriques | H20: 764182.3
... D122: Total général | E122: 2.2891944e+08 | G122: Contrôle des ambiances de travail, aération, ventilation | H122: 240772.54
G123: Contrôle des appareils de levage et manutention | H123: 120879.25
G124: Contrôle des ascenseurs et monte-charges | H124: 6323.7235
G125: Contrôle des dispositifs de protection incendie | H125: 26400.35
G126: Contrôle des équipements de protection | H126: 18192.579
G127: Contrôle des installations à énergie thermique | H127: 110845.07
G128: Contrôle des Installations Classées pour la Protection de l'Environnement (ICPE) | H128: 75398.81
G129: Contrôle des installations électriques et éclairage | H129: 230011.8
G130: Contrôle des installations sous pression | H130: 29838.21
G131: Contrôle des matèriels, engins et installations utilisés sur chantiers du BTP | H131: 4817
G132: Contrôle des portes et portails | H132: 19058.37
G133: Contrôle environnemental | H133: 7194.11
G134: Contrôle technique automobile | H134: 16158.314
... G554: Total général | H554: 2.2891944e+08
